Workbook

Sheet Project Work - Data (Corrupted)
A1: Order Date | B1: Order Number | C1: Product | D1: Quantity | E1: Price Per Unit | F1: Cost per Unit | G1: Revenue | H1: Costs | I1: Profit | J1: Order Survey Response | K1: Customer ID | L1: Customer Category | M1: Customer Tenure
A2: 45554.63 | B2: 24-3624 | C2: P026 | D2: 15 | E2: 280 | F2: 70 | J2: Dissatisfied | K2: CP-2167 | L2: Corporate & Professional | M2: 10.278064
A3: 43388.154 | B3: 18-3596 | C3: P089 | D3: 8 | E3: 102 | F3: 51 | J3: Neither | K3: CP-2216 | L3: Corporate & Professional | M3: 13.299525
A4: 43463.082 | B4: 18-1394 | C4: P100 | D4: 13 | E4: 46 | J4: Dissatisfied | K4: FE-6557 | L4: Facilities & Services | M4: 9.3226776
A5: 44541.778 | B5: 21-2559 | C5: P034 | D5: 4 | E5: 114 | F5: 57 | J5: Neither | K5: FE-6685 | L5: Facilities & Services | M5: 10.06992
A6: 44789.861 | B6: 22-4827 | C6: P064 | D6: 2 | E6: 231 | F6: 77 | J6: Neither | K6: EE-4169 | L6: Education | M6: 15.24191
A7: 44100.48 | B7: 20-3867 | C7: P040 | D7: 3 | E7: 160 | F7: 80 | J7: Satisfied | K7: HS-7790 | L7: Healthcare & Safety | M7: 12.169267
A8: 43152.556 | B8: 18-1317 | C8: P006 | D8: 6 | E8: 38 | J8: Neither | K8: CT-3882 | L8: Creative & Technology | M8: 11.749994
A9: 43842.898 | B9: 20-3505 | C9: P006 | D9: 11 | J9: Neither | K9: HS-7242 | L9: Healthcare & Safety | M9: 11.048445
A10: 44474.758 | B10: 21-4413 | C10: P094 | D10: 4 | E10: 80 | F10: 20 | J10: Neither | K10: SR-9557 | L10: Sports & Recreation | M10: 10.988762
A11: 44218.773 | B11: 21-3023 | C11: P054 | E11: 144 | F11: 48 | J11: Neither | K11: SR-9989 | L11: Sports & Recreation | M11: 15.602184
A12: 43898.47 | B12: 20-4356 | C12: P043 | D12: 20 | E12: 184 | F12: 92 | J12: Satisfied | K12: EE-4770 | L12: Education | M12: 12.957303
A13: 44085.41 | B13: 20-3883 | C13: P052 | D13: 2 | E13: 352 | F13: 88 | J13: Satisfied | K13: CT-3754 | L13: Creative & Technology | M13: 8.2871811
A14: 43671.067 | B14: 19-3629 | C14: P005 | D14: 5 | E14: 76 | F14: 19 | J14: Neither | K14: CT-3949 | L14: Creative & Technology | M14: 9.8384363
A15: 43997.695 | B15: 20-2783 | C15: P076 | D15: 14 | F15: 47 | J15: Neither | K15: SR-9729 | L15: Sports & Recreation | M15: 12.16373
A16: 44224.976 | B16: 21-3864 | C16: P014 | D16: 16 | E16: 166 | F16: 83 | J16: Satisfied | K16: CT-3881 | L16: Creative & Technology | M16: 13.459801
A17: 44117.051 | B17: 20-1968 | C17: P023 | D17: 7 | F17: 42 | J17: Dissatisfied | K17: CG-1547 | L17: Community & Government | M17: 11.631646
A18: 43834.899 | B18: 20-1980 | C18: P071 | D18: 10 | F18: 70 | J18: Neither | K18: SR-9132 | L18: Sports & Recreation | M18: 12.865075
A19: 44320.298 | B19: 21-4557 | C19: P060 | D19: 6 | E19: 300 | F19: 75 | J19: Neither | K19: SR-9989 | L19: Sports & Recreation | M19: 15.602184
A20: 43253.266 | B20: 18-4105 | C20: P091 | D20: 12 | E20: 204 | F20: 51 | J20: Neither | K20: EE-46 | L20: Education | M20: 9.8238489
A21: 43499.755 | B21: 19-4897 | C21: P094 | D21: 3 | E21: 80 | J21: Satisfied | K21: SR-955 | L21: Sports & Recreation | M21: 12.072415
A22: 44125.238 | B22: 20-4960 | C22: P028 | D22: 17 | E22: 156 | F22: 78 | J22: Neither | K22: CG-151 | L22: Community & Government | M22: 15.140904
A23: 44357.627 | B23: 21-2115 | C23: P065 | D23: 9 | E23: 50 | J23: Dissatisfied | K23: EE-4774 | L23: Education | M23: 15.126377
A24: 44807.029 | B24: 22-4758 | C24: P026 | D24: 1 | E24: 280 | J24: Neither | K24: HS-7790 | L24: Healthcare & Safety | M24: 12.169267
A25: 43068.002 | B25: 17-1449 | C25: P098 | D25: 5 | E25: 201 | J25: Satisfied | K25: FE-6410 | L25: Facilities & Services | M25: 13.717776
A26: 44066.937 | B26: 20-2961 | C26: P023 | D26: 3 | E26: 126 | F26: 42 | J26: Dissatisfied | K26: SR-9880 | L26: Sports & Recreation | M26: 9.7467096
A27: 43608.539 | B27: 19-3898 | C27: P002 | D27: 12 | E27: 144 | F27: 36 | J27: Satisfied | K27: HS-7440 | L27: Healthcare & Safety | M27: 13.407341
A28: 43624.553 | B28: 19-4584 | C28: P024 | D28: 5 | E28: 66 | J28: Neither | K28: HS-7440 | L28: Healthcare & Safety | M28: 13.407341
A29: 43952.992 | B29: 20-4784 | C29: P030 | D29: 14 | E29: 81 | F29: 27 | J29: Neither | K29: SR-9497 | L29: Sports & Recreation | M29: 14.697745
A30: 44248.206 | B30: 21-2025 | C30: P043 | D30: 18 | E30: 184 | F30: 92 | J30: Satisfied | K30: SR-9668 | L30: Sports & Recreation | M30: 11.128722
A31: 43717.585 | B31: 19-3656 | C31: P048 | D31: 4 | E31: 252 | F31: 63 | J31: Neither | K31: SR-9563 | L31: Sports & Recreation | M31: 14.163035
A32: 43447.602 | B32: 18-1412 | C32: P071 | D32: 10 | E32: 210 | F32: 70 | J32: Neither | K32: HS-7291 | L32: Healthcare & Safety | M32: 10.42743
A33: 43413.651 | B33: 18-3342 | C33: P087 | D33: 12 | E33: 176 | F33: 88 | J33: Neither | K33: SR-9632 | L33: Sports & Recreation | M33: 11.006398
A34: 44213.146 | B34: 21-2874 | C34: P043 | D34: 15 | F34: 92 | J34: Neither | K34: FE-6617 | L34: Facilities & Services | M34: 15.487214
A35: 43907.019 | B35: 20-1831 | C35: P096 | D35: 17 | J35: Neither | K35: CP-295 | L35: Corporate & Professional | M35: 12.844063
A36: 43704.679 | B36: 19-2562 | C36: P003 | D36: 7 | E36: 189 | F36: 63 | J36: Dissatisfied | K36: CP-2330 | L36: Corporate & Professional | M36: 9.4200113
A37: 44358.082 | B37: 21-4466 | C37: P084 | D37: 7 | J37: Neither | K37: FE-621 | L37: Facilities & Services | M37: 11.410471
A38: 44285.752 | B38: 21-3075 | C38: P085 | D38: 18 | F38: 80 | J38: Satisfied | K38: HS-7220 | L38: Healthcare & Safety | M38: 7.1104128
A39: 44467.408 | B39: 21-3988 | C39: P025 | D39: 11 | F39: 70 | J39: Satisfied | K39: SR-9797 | L39: Sports & Recreation | M39: 11.406234
A40: 43336.7 | B40: 18-2953 | C40: P021 | D40: 1 | E40: 207 | F40: 69 | J40: Neither | K40: SR-9639 | L40: Sports & Recreation | M40: 12.487915
...

Sheet Price Averages
A3: Row Labels | B3: Average of Price Per Unit
A4: P001 | B4: 108 | D4: P001 | E4: 108
A5: P002 | B5: 144 | D5: P002 | E5: 144
A6: P003 | B6: 189 | D6: P003 | E6: 189
A7: P004 | B7: 189 | D7: P004 | E7: 189
A8: P005 | B8: 76 | D8: P005 | E8: 76
A9: P006 | B9: 38 | D9: P006 | E9: 38
A10: P007 | B10: 225 | D10: P007 | E10: 225
A11: P008 | B11: 225 | D11: P008 | E11: 225
A12: P009 | B12: 255 | D12: P009 | E12: 255
A13: P010 | B13: 144 | D13: P010 | E13: 144
A14: P011 | B14: 264 | D14: P011 | E14: 264
A15: P012 | B15: 30 | D15: P012 | E15: 30
... A103: P100 | B103: 46 | D103: P100 | E103: 46
A104: (blank)
A105: Grand Total | B105: 173.30017

Sheet Cost Averages
A3: Row Labels | B3: Average of Cost per Unit
A4: P001 | B4: 36 | D4: P001 | E4: 36
A5: P002 | B5: 36 | D5: P002 | E5: 36
A6: P003 | B6: 63 | D6: P003 | E6: 63
A7: P004 | B7: 63 | D7: P004 | E7: 63
A8: P005 | B8: 19 | D8: P005 | E8: 19
A9: P006 | B9: 19 | D9: P006 | E9: 19
A10: P007 | B10: 75 | D10: P007 | E10: 75
A11: P008 | B11: 75 | D11: P008 | E11: 75
A12: P009 | B12: 85 | D12: P009 | E12: 85
A13: P010 | B13: 36 | D13: P010 | E13: 36
A14: P011 | B14: 88 | D14: P011 | E14: 88
A15: P012 | B15: 15 | D15: P012 | E15: 15
... A103: P100 | B103: 23 | D103: P100 | E103: 23
A104: (blank)
A105: Grand Total | B105: 57.57266

Sheet PivotTable Full Data
A3: Row Labels | B3: Average of Profit | C3: StdDev of Profit | D3: Count of Profit | E3: Sum of Profit
A4: A | B4: 1448 | C4: 822.85625 | D4: 6 | E4: 8688 | G4: A | H4: 1448 | I4: 822.85625 | J4: 6 | K4: 8688 | M4: =(H4-H5)/SQRT((I4^2/J4)+(I5^2/J5)) -> 0.56264453
A5: B | B5: 1216.9474 | C5: 1029.5546 | D5: 19 | E5: 23122 | G5: B | H5: 1216.9474 | I5: 1029.5546 | J5: 19 | K5: 23122 | M5: =(H5-H6)/SQRT((I5^2/J5)+(I6^2/J6)) -> 0.089139479
A6: C | B6: 1193.6765 | C6: 1123.0273 | D6: 102 | E6: 121755 | G6: C | H6: 1193.6765 | I6: 1123.0273 | J6: 102 | K6: 121755 | M6: =(H6-H7)/SQRT((I6^2/J6)+(I7^2/J7)) -> -0.94857796
A7: D | B7: 1316.4048 | C7: 1212.4246 | D7: 336 | E7: 442312 | G7: D | H7: 1316.4048 | I7: 1212.4246 | J7: 336 | K7: 442312 | M7: =(H7-H8)/SQRT((I7^2/J7)+(I8^2/J8)) -> 1.909998
A8: E | B8: 1169.192 | C8: 1083.6076 | D8: 750 | E8: 876894 | G8: E | H8: 1169.192 | I8: 1083.6076 | J8: 750 | K8: 876894 | M8: =(H8-H9)/SQRT((I8^2/J8)+(I9^2/J9)) -> -0.98120767
A9: F | B9: 1219.6756 | C9: 1116.7021 | D9: 1153 | E9: 1406286 | G9: F | H9: 1219.6756 | I9: 1116.7021 | J9: 1153 | K9: 1406286 | M9: =(H9-H10)/SQRT((I9^2/J9)+(I10^2/J10)) -> 0.091626056
A10: G | B10: 1215.0917 | C10: 1134.1437 | D10: 905 | E10: 1099658 | G10: G | H10: 1215.0917 | I10: 1134.1437 | J10: 905 | K10: 1099658 | M10: =(H10-H11)/SQRT((I10^2/J10)+(I11^2/J11)) -> -0.12973334
A11: H | B11: 1223.3726 | C11: 1122.5755 | D11: 475 | E11: 581102 | G11: H | H11: 1223.3726 | I11: 1122.5755 | J11: 475 | K11: 581102 | M11: =(H11-H12)/SQRT((I11^2/J11)+(I12^2/J12)) -> 2.7333454
A12: I | B12: 910.83929 | C12: 763.91613 | D12: 56 | E12: 51007 | G12: I | H12: 910.83929 | I12: 763.91613 | J12: 56 | K12: 51007 | M12: =(H12-H13)/SQRT((I12^2/J12)+(I13^2/J13)) -> -1.1295798
A13: J | B13: 1407.0909 | C13: 1417.1919 | D13: 11 | E13: 15478 | G13: J | H13: 1407.0909 | I13: 1417.1919 | J13: 11 | K13: 15478 | M13: =(H13-H14)/SQRT((I13^2/J13)+(I14^2/J14)) -> 2.1642064
A14: K | B14: 470 | C14: 98.994949 | D14: 2 | E14: 940 | G14: K | H14: 470 | I14: 98.994949 | J14: 2 | K14: 940
A15: Grand Total | B15: 1212.9075 | C15: 1119.8254 | D15: 3815 | E15: 4627242

Sheet Project Work - Data Del Rows
A1: Order Date | B1: Order Number | C1: Product | D1: Quantity | E1: Price Per Unit | F1: Fixed Price Per Unit | G1: Cost per Unit | H1: Fixed Cost Per Unit | I1: Revenue | J1: Costs | K1: Profit | L1: Order Survey Response | M1: Customer ID | N1: Customer Category | O1: Customer Tenure | P1: Subset Label | Q1: Subset | R1: Subset Check
A2: 42258.411 | B2: 15-4254 | C2: P037 | D2: 1 | E2: 160 | F2: =IF(E2="",_xlfn.XLOOKUP(C2,'Price Averages'!$D$4:$D$103,'Price Averages'!$E$4:$E$103, "FALSE"), E2) -> 160 | G2: 80 | H2: =IF(G2="", _xlfn.XLOOKUP(C2, 'Cost Averages'!$D$4:$D$103,'Cost Averages'!$E$4:$E$103, "FALSE"),G2) -> 80 | I2: =D2*F2 -> 160 | J2: =D2*H2 -> 80 | K2: =I2-J2 -> 80 | L2: Neither | M2: HS-7862 | N2: Healthcare & Safety | O2: 14.423323 | P2: =CHAR(64+(YEAR(A2)-2014)) -> A | Q2: =YEAR(A2) -> 2015 | R2: =IF(P2=CHAR(64 + (YEAR(A2) - 2014)), 0, 1) -> 0
A3: 42178.711 | B3: 15-2073 | C3: P055 | D3: 8 | E3: 360 | F3: =IF(E3="",_xlfn.XLOOKUP(C3,'Price Averages'!$D$4:$D$103,'Price Averages'!$E$4:$E$103, "FALSE"), E3) -> 360 | G3: 90 | H3: =IF(G3="", _xlfn.XLOOKUP(C3, 'Cost Averages'!$D$4:$D$103,'Cost Averages'!$E$4:$E$103, "FALSE"),G3) -> 90 | I3: =D3*F3 -> 2880 | J3: =D3*H3 -> 720 | K3: =I3-J3 -> 2160 | L3: Neither | M3: CP-2960 | N3: Corporate & Professional | O3: 13.062293 | P3: =CHAR(64+(YEAR(A3)-2014)) -> A | Q3: =YEAR(A3) -> 2015 | R3: =IF(P3=CHAR(64 + (YEAR(A3) - 2014)), 0, 1) -> 0
A4: 42368.549 | B4: 15-3490 | C4: P057 | D4: 9 | E4: 252 | F4: =IF(E4="",_xlfn.XLOOKUP(C4,'Price Averages'!$D$4:$D$103,'Price Averages'!$E$4:$E$103, "FALSE"), E4) -> 252 | G4: 63 | H4: =IF(G4="", _xlfn.XLOOKUP(C4, 'Cost Averages'!$D$4:$D$103,'Cost Averages'!$E$4:$E$103, "FALSE"),G4) -> 63 | I4: =D4*F4 -> 2268 | J4: =D4*H4 -> 567 | K4: =I4-J4 -> 1701 | L4: Satisfied | M4: CT-3606 | N4: Creative & Technology | O4: 12.173452 | P4: =CHAR(64+(YEAR(A4)-2014)) -> A | Q4: =YEAR(A4) -> 2015 | R4: =IF(P4=CHAR(64 + (YEAR(A4) - 2014)), 0, 1) -> 0
A5: 42297.389 | B5: 15-3098 | C5: P031 | D5: 13 | F5: =IF(E5="",_xlfn.XLOOKUP(C5,'Price Averages'!$D$4:$D$103,'Price Averages'!$E$4:$E$103, "FALSE"), E5) -> 146 | G5: 73 | H5: =IF(G5="", _xlfn.XLOOKUP(C5, 'Cost Averages'!$D$4:$D$103,'Cost Averages'!$E$4:$E$103, "FALSE"),G5) -> 73 | I5: =D5*F5 -> 1898 | J5: =D5*H5 -> 949 | K5: =I5-J5 -> 949 | L5: Neither | M5: HS-770 | N5: Healthcare & Safety | O5: 12.148237 | P5: =CHAR(64+(YEAR(A5)-2014)) -> A | Q5: =YEAR(A5) -> 2015 | R5: =IF(P5=CHAR(64 + (YEAR(A5) - 2014)), 0, 1) -> 0
A6: 42322.453 | B6: 15-3015 | C6: P098 | D6: 17 | E6: 201 | F6: =IF(E6="",_xlfn.XLOOKUP(C6,'Price Averages'!$D$4:$D$103,'Price Averages'!$E$4:$E$103, "FALSE"), E6) -> 201 | G6: 67 | H6: =IF(G6="", _xlfn.XLOOKUP(C6, 'Cost Averages'!$D$4:$D$103,'Cost Averages'!$E$4:$E$103, "FALSE"),G6) -> 67 | I6: =D6*F6 -> 3417 | J6: =D6*H6 -> 1139 | K6: =I6-J6 -> 2278 | L6: Satisfied | M6: EE-4613 | N6: Education | O6: 15.26855 | P6: =CHAR(64+(YEAR(A6)-2014)) -> A | Q6: =YEAR(A6) -> 2015 | R6: =IF(P6=CHAR(64 + (YEAR(A6) - 2014)), 0, 1) -> 0
A7: 42216.891 | B7: 15-4617 | C7: P075 | D7: 19 | E7: 160 | F7: =IF(E7="",_xlfn.XLOOKUP(C7,'Price Averages'!$D$4:$D$103,'Price Averages'!$E$4:$E$103, "FALSE"), E7) -> 160 | G7: 80 | H7: =IF(G7="", _xlfn.XLOOKUP(C7, 'Cost Averages'!$D$4:$D$103,'Cost Averages'!$E$4:$E$103, "FALSE"),G7) -> 80 | I7: =D7*F7 -> 3040 | J7: =D7*H7 -> 1520 | K7: =I7-J7 -> 1520 | L7: Neither | M7: EE-4917 | N7: Education | O7: 11.756375 | P7: =CHAR(64+(YEAR(A7)-2014)) -> A | Q7: =YEAR(A7) -> 2015 | R7: =IF(P7=CHAR(64 + (YEAR(A7) - 2014)), 0, 1) -> 0
A8: 42720.978 | B8: 16-1451 | C8: P064 | D8: 1 | E8: 231 | F8: =IF(E8="",_xlfn.XLOOKUP(C8,'Price Averages'!$D$4:$D$103,'Price Averages'!$E$4:$E$103, "FALSE"), E8) -> 231 | G8: 77 | H8: =IF(G8="", _xlfn.XLOOKUP(C8, 'Cost Averages'!$D$4:$D$103,'Cost Averages'!$E$4:$E$103, "FALSE"),G8) -> 77 | I8: =D8*F8 -> 231 | J8: =D8*H8 -> 77 | K8: =I8-J8 -> 154 | L8: Neither | M8: CT-3498 | N8: Creative & Technology | O8: 10.588336 | P8: =CHAR(64+(YEAR(A8)-2014)) -> B | Q8: =YEAR(A8) -> 2016 | R8: =IF(P8=CHAR(64 + (YEAR(A8) - 2014)), 0, 1) -> 0
A9: 42673.243 | B9: 16-1836 | C9: P006 | D9: 2 | F9: =IF(E9="",_xlfn.XLOOKUP(C9,'Price Averages'!$D$4:$D$103,'Price Averages'!$E$4:$E$103, "FALSE"), E9) -> 38 | G9: 19 | H9: =IF(G9="", _xlfn.XLOOKUP(C9, 'Cost Averages'!$D$4:$D$103,'Cost Averages'!$E$4:$E$103, "FALSE"),G9) -> 19 | I9: =D9*F9 -> 76 | J9: =D9*H9 -> 38 | K9: =I9-J9 -> 38 | L9: Neither | M9: CG-1672 | N9: Community & Government | O9: 11.655356 | P9: =CHAR(64+(YEAR(A9)-2014)) -> B | Q9: =YEAR(A9) -> 2016 | R9: =IF(P9=CHAR(64 + (YEAR(A9) - 2014)), 0, 1) -> 0
A10: 42673.971 | B10: 16-3460 | C10: P083 | D10: 2 | E10: 90 | F10: =IF(E10="",_xlfn.XLOOKUP(C10,'Price Averages'!$D$4:$D$103,'Price Averages'!$E$4:$E$103, "FALSE"), E10) -> 90 | H10: =IF(G10="", _xlfn.XLOOKUP(C10, 'Cost Averages'!$D$4:$D$103,'Cost Averages'!$E$4:$E$103, "FALSE"),G10) -> 45 | I10: =D10*F10 -> 180 | J10: =D10*H10 -> 90 | K10: =I10-J10 -> 90 | L10: Satisfied | M10: CT-3920 | N10: Creative & Technology | O10: 14.661477 | P10: =CHAR(64+(YEAR(A10)-2014)) -> B | Q10: =YEAR(A10) -> 2016 | R10: =IF(P10=CHAR(64 + (YEAR(A10) - 2014)), 0, 1) -> 0
A11: 42447.175 | B11: 16-2553 | C11: P100 | D11: 5 | E11: 46 | F11: =IF(E11="",_xlfn.XLOOKUP(C11,'Price Averages'!$D$4:$D$103,'Price Averages'!$E$4:$E$103, "FALSE"), E11) -> 46 | G11: 23 | H11: =IF(G11="", _xlfn.XLOOKUP(C11, 'Cost Averages'!$D$4:$D$103,'Cost Averages'!$E$4:$E$103, "FALSE"),G11) -> 23 | I11: =D11*F11 -> 230 | J11: =D11*H11 -> 115 | K11: =I11-J11 -> 115 | L11: Satisfied | M11: EE-46 | N11: Education | O11: 9.8238489 | P11: =CHAR(64+(YEAR(A11)-2014)) -> B | Q11: =YEAR(A11) -> 2016 | R11: =IF(P11=CHAR(64 + (YEAR(A11) - 2014)), 0, 1) -> 0
A12: 42695.685 | B12: 16-4606 | C12: P008 | D12: 6 | E12: 225 | F12: =IF(E12="",_xlfn.XLOOKUP(C12,'Price Averages'!$D$4:$D$103,'Price Averages'!$E$4:$E$103, "FALSE"), E12) -> 225 | G12: 75 | H12: =IF(G12="", _xlfn.XLOOKUP(C12, 'Cost Averages'!$D$4:$D$103,'Cost Averages'!$E$4:$E$103, "FALSE"),G12) -> 75 | I12: =D12*F12 -> 1350 | J12: =D12*H12 -> 450 | K12: =I12-J12 -> 900 | L12: Neither | M12: SR-930 | N12: Sports & Recreation | O12: 14.690199 | P12: =CHAR(64+(YEAR(A12)-2014)) -> B | Q12: =YEAR(A12) -> 2016 | R12: =IF(P12=CHAR(64 + (YEAR(A12) - 2014)), 0, 1) -> 0
A13: 42693.272 | B13: 16-2390 | C13: P043 | D13: 8 | E13: 184 | F13: =IF(E13="",_xlfn.XLOOKUP(C13,'Price Averages'!$D$4:$D$103,'Price Averages'!$E$4:$E$103, "FALSE"), E13) -> 184 | G13: 92 | H13: =IF(G13="", _xlfn.XLOOKUP(C13, 'Cost Averages'!$D$4:$D$103,'Cost Averages'!$E$4:$E$103, "FALSE"),G13) -> 92 | I13: =D13*F13 -> 1472 | J13: =D13*H13 -> 736 | K13: =I13-J13 -> 736 | L13: Neither | M13: HS-712 | N13: Healthcare & Safety | O13: 10.428287 | P13: =CHAR(64+(YEAR(A13)-2014)) -> B | Q13: =YEAR(A13) -> 2016 | R13: =IF(P13=CHAR(64 + (YEAR(A13) - 2014)), 0, 1) -> 0
A14: 42656.038 | B14: 16-1050 | C14: P058 | D14: 8 | F14: =IF(E14="",_xlfn.XLOOKUP(C14,'Price Averages'!$D$4:$D$103,'Price Averages'!$E$4:$E$103, "FALSE"), E14) -> 356 | G14: 89 | H14: =IF(G14="", _xlfn.XLOOKUP(C14, 'Cost Averages'!$D$4:$D$103,'Cost Averages'!$E$4:$E$103, "FALSE"),G14) -> 89 | I14: =D14*F14 -> 2848 | J14: =D14*H14 -> 712 | K14: =I14-J14 -> 2136 | L14: Neither | M14: EE-4357 | N14: Education | O14: 13.466363 | P14: =CHAR(64+(YEAR(A14)-2014)) -> B | Q14: =YEAR(A14) -> 2016 | R14: =IF(P14=CHAR(64 + (YEAR(A14) - 2014)), 0, 1) -> 0
A15: 42720.868 | B15: 16-4872 | C15: P055 | D15: 9 | F15: =IF(E15="",_xlfn.XLOOKUP(C15,'Price Averages'!$D$4:$D$103,'Price Averages'!$E$4:$E$103, "FALSE"), E15) -> 360 | G15: 90 | H15: =IF(G15="", _xlfn.XLOOKUP(C15, 'Cost Averages'!$D$4:$D$103,'Cost Averages'!$E$4:$E$103, "FALSE"),G15) -> 90 | I15: =D15*F15 -> 3240 | J15: =D15*H15 -> 810 | K15: =I15-J15 -> 2430 | L15: Satisfied | M15: SR-9808 | N15: Sports & Recreation | O15: 10.816866 | P15: =CHAR(64+(YEAR(A15)-2014)) -> B | Q15: =YEAR(A15) -> 2016 | R15: =IF(P15=CHAR(64 + (YEAR(A15) - 2014)), 0, 1) -> 0
A16: 42476.479 | B16: 16-2216 | C16: P074 | D16: 10 | E16: 352 | F16: =IF(E16="",_xlfn.XLOOKUP(C16,'Price Averages'!$D$4:$D$103,'Price Averages'!$E$4:$E$103, "FALSE"), E16) -> 352 | H16: =IF(G16="", _xlfn.XLOOKUP(C16, 'Cost Averages'!$D$4:$D$103,'Cost Averages'!$E$4:$E$103, "FALSE"),G16) -> 88 | I16: =D16*F16 -> 3520 | J16: =D16*H16 -> 880 | K16: =I16-J16 -> 2640 | L16: Dissatisfied | M16: HS-7291 | N16: Healthcare & Safety | O16: 10.42743 | P16: =CHAR(64+(YEAR(A16)-2014)) -> B | Q16: =YEAR(A16) -> 2016 | R16: =IF(P16=CHAR(64 + (YEAR(A16) - 2014)), 0, 1) -> 0
A17: 42681.511 | B17: 16-3455 | C17: P013 | D17: 11 | E17: 58 | F17: =IF(E17="",_xlfn.XLOOKUP(C17,'Price Averages'!$D$4:$D$103,'Price Averages'!$E$4:$E$103, "FALSE"), E17) -> 58 | H17: =IF(G17="", _xlfn.XLOOKUP(C17, 'Cost Averages'!$D$4:$D$103,'Cost Averages'!$E$4:$E$103, "FALSE"),G17) -> 29 | I17: =D17*F17 -> 638 | J17: =D17*H17 -> 319 | K17: =I17-J17 -> 319 | L17: Neither | M17: EE-450 | N17: Education | O17: 8.3272838 | P17: =CHAR(64+(YEAR(A17)-2014)) -> B | Q17: =YEAR(A17) -> 2016 | R17: =IF(P17=CHAR(64 + (YEAR(A17) - 2014)), 0, 1) -> 0
A18: 42614.075 | B18: 16-2604 | C18: P067 | D18: 11 | E18: 144 | F18: =IF(E18="",_xlfn.XLOOKUP(C18,'Price Averages'!$D$4:$D$103,'Price Averages'!$E$4:$E$103, "FALSE"), E18) -> 144 | G18: 36 | H18: =IF(G18="", _xlfn.XLOOKUP(C18, 'Cost Averages'!$D$4:$D$103,'Cost Averages'!$E$4:$E$103, "FALSE"),G18) -> 36 | I18: =D18*F18 -> 1584 | J18: =D18*H18 -> 396 | K18: =I18-J18 -> 1188 | L18: Satisfied | M18: CG-137 | N18: Community & Government | O18: 12.796588 | P18: =CHAR(64+(YEAR(A18)-2014)) -> B | Q18: =YEAR(A18) -> 2016 | R18: =IF(P18=CHAR(64 + (YEAR(A18) - 2014)), 0, 1) -> 0
A19: 42615.366 | B19: 16-4442 | C19: P072 | D19: 12 | E19: 132 | F19: =IF(E19="",_xlfn.XLOOKUP(C19,'Price Averages'!$D$4:$D$103,'Price Averages'!$E$4:$E$103, "FALSE"), E19) -> 132 | G19: 44 | H19: =IF(G19="", _xlfn.XLOOKUP(C19, 'Cost Averages'!$D$4:$D$103,'Cost Averages'!$E$4:$E$103, "FALSE"),G19) -> 44 | I19: =D19*F19 -> 1584 | J19: =D19*H19 -> 528 | K19: =I19-J19 -> 1056 | L19: Dissatisfied | M19: FE-6892 | N19: Facilities & Services | O19: 14.817898 | P19: =CHAR(64+(YEAR(A19)-2014)) -> B | Q19: =YEAR(A19) -> 2016 | R19: =IF(P19=CHAR(64 + (YEAR(A19) - 2014)), 0, 1) -> 0
A20: 42614.684 | B20: 16-1985 | C20: P074 | D20: 13 | E20: 352 | F20: =IF(E20="",_xlfn.XLOOKUP(C20,'Price Averages'!$D$4:$D$103,'Price Averages'!$E$4:$E$103, "FALSE"), E20) -> 352 | G20: 88 | H20: =IF(G20="", _xlfn.XLOOKUP(C20, 'Cost Averages'!$D$4:$D$103,'Cost Averages'!$E$4:$E$103, "FALSE"),G20) -> 88 | I20: =D20*F20 -> 4576 | J20: =D20*H20 -> 1144 | K20: =I20-J20 -> 3432 | L20: Satisfied | M20: CP-2325 | N20: Corporate & Professional | O20: 11.701919 | P20: =CHAR(64+(YEAR(A20)-2014)) -> B | Q20: =YEAR(A20) -> 2016 | R20: =IF(P20=CHAR(64 + (YEAR(A20) - 2014)), 0, 1) -> 0
A21: 42709.937 | B21: 16-4839 | C21: P017 | D21: 16 | E21: 120 | F21: =IF(E21="",_xlfn.XLOOKUP(C21,'Price Averages'!$D$4:$D$103,'Price Averages'!$E$4:$E$103, "FALSE"), E21) -> 120 | G21: 30 | H21: =IF(G21="", _xlfn.XLOOKUP(C21, 'Cost Averages'!$D$4:$D$103,'Cost Averages'!$E$4:$E$103, "FALSE"),G21) -> 30 | I21: =D21*F21 -> 1920 | J21: =D21*H21 -> 480 | K21: =I21-J21 -> 1440 | L21: Satisfied | M21: CP-2926 | N21: Corporate & Professional | O21: 8.1743378 | P21: =CHAR(64+(YEAR(A21)-2014)) -> B | Q21: =YEAR(A21) -> 2016 | R21: =IF(P21=CHAR(64 + (YEAR(A21) - 2014)), 0, 1) -> 0
A22: 42676.558 | B22: 16-1558 | C22: P040 | D22: 16 | E22: 160 | F22: =IF(E22="",_xlfn.XLOOKUP(C22,'Price Averages'!$D$4:$D$103,'Price Averages'!$E$4:$E$103, "FALSE"), E22) -> 160 | G22: 80 | H22: =IF(G22="", _xlfn.XLOOKUP(C22, 'Cost Averages'!$D$4:$D$103,'Cost Averages'!$E$4:$E$103, "FALSE"),G22) -> 80 | I22: =D22*F22 -> 2560 | J22: =D22*H22 -> 1280 | K22: =I22-J22 -> 1280 | L22: Neither | M22: FE-6981 | N22: Facilities & Services | O22: 10.517826 | P22: =CHAR(64+(YEAR(A22)-2014)) -> B | Q22: =YEAR(A22) -> 2016 | R22: =IF(P22=CHAR(64 + (YEAR(A22) - 2014)), 0, 1) -> 0
A23: 42686.704 | B23: 16-4049 | C23: P038 | D23: 18 | E23: 240 | F23: =IF(E23="",_xlfn.XLOOKUP(C23,'Price Averages'!$D$4:$D$103,'Price Averages'!$E$4:$E$103, "FALSE"), E23) -> 240 | G23: 80 | H23: =IF(G23="", _xlfn.XLOOKUP(C23, 'Cost Averages'!$D$4:$D$103,'Cost Averages'!$E$4:$E$103, "FALSE"),G23) -> 80 | I23: =D23*F23 -> 4320 | J23: =D23*H23 -> 1440 | K23: =I23-J23 -> 2880 | L23: Neither | M23: SR-9468 | N23: Sports & Recreation | O23: 10.010333 | P23: =CHAR(64+(YEAR(A23)-2014)) -> B | Q23: =YEAR(A23) -> 2016 | R23: =IF(P23=CHAR(64 + (YEAR(A23) - 2014)), 0, 1) -> 0
A24: 42485.261 | B24: 16-3871 | C24: P056 | D24: 18 | F24: =IF(E24="",_xlfn.XLOOKUP(C24,'Price Averages'!$D$4:$D$103,'Price Averages'!$E$4:$E$103, "FALSE"), E24) -> 72 | G24: 36 | H24: =IF(G24="", _xlfn.XLOOKUP(C24, 'Cost Averages'!$D$4:$D$103,'Cost Averages'!$E$4:$E$103, "FALSE"),G24) -> 36 | I24: =D24*F24 -> 1296 | J24: =D24*H24 -> 648 | K24: =I24-J24 -> 648 | L24: Dissatisfied | M24: CT-3881 | N24: Creative & Technology | O24: 13.459801 | P24: =CHAR(64+(YEAR(A24)-2014)) -> B | Q24: =YEAR(A24) -> 2016 | R24: =IF(P24=CHAR(64 + (YEAR(A24) - 2014)), 0, 1) -> 0
A25: 42641.299 | B25: 16-1896 | C25: P005 | D25: 20 | F25: =IF(E25="",_xlfn.XLOOKUP(C25,'Price Averages'!$D$4:$D$103,'Price Averages'!$E$4:$E$103, "FALSE"), E25) -> 76 | G25: 19 | H25: =IF(G25="", _xlfn.XLOOKUP(C25, 'Cost Averages'!$D$4:$D$103,'Cost Averages'!$E$4:$E$103, "FALSE"),G25) -> 19 | I25: =D25*F25 -> 1520 | J25: =D25*H25 -> 380 | K25: =I25-J25 -> 1140 | L25: Neither | M25: CT-3174 | N25: Creative & Technology | O25: 15.187892 | P25: =CHAR(64+(YEAR(A25)-2014)) -> B | Q25: =YEAR(A25) -> 2016 | R25: =IF(P25=CHAR(64 + (YEAR(A25) - 2014)), 0, 1) -> 0
A26: 42720.244 | B26: 16-1417 | C26: P081 | D26: 20 | E26: 50 | F26: =IF(E26="",_xlfn.XLOOKUP(C26,'Price Averages'!$D$4:$D$103,'Price Averages'!$E$4:$E$103, "FALSE"), E26) -> 50 | H26: =IF(G26="", _xlfn.XLOOKUP(C26, 'Cost Averages'!$D$4:$D$103,'Cost Averages'!$E$4:$E$103, "FALSE"),G26) -> 25 | I26: =D26*F26 -> 1000 | J26: =D26*H26 -> 500 | K26: =I26-J26 -> 500 | L26: Neither | M26: CP-2629 | N26: Corporate & Professional | O26: 10.411813 | P26: =CHAR(64+(YEAR(A26)-2014)) -> B | Q26: =YEAR(A26) -> 2016 | R26: =IF(P26=CHAR(64 + (YEAR(A26) - 2014)), 0, 1) -> 0
A27: 43080.739 | B27: 17-2199 | C27: P009 | D27: 1 | E27: 255 | F27: =IF(E27="",_xlfn.XLOOKUP(C27,'Price Averages'!$D$4:$D$103,'Price Averages'!$E$4:$E$103, "FALSE"), E27) -> 255 | G27: 85 | H27: =IF(G27="", _xlfn.XLOOKUP(C27, 'Cost Averages'!$D$4:$D$103,'Cost Averages'!$E$4:$E$103, "FALSE"),G27) -> 85 | I27: =D27*F27 -> 255 | J27: =D27*H27 -> 85 | K27: =I27-J27 -> 170 | L27: Neither | M27: FE-629 | N27: Facilities & Services | O27: 11.311041 | P27: =CHAR(64+(YEAR(A27)-2014)) -> C | Q27: =YEAR(A27) -> 2017 | R27: =IF(P27=CHAR(64 + (YEAR(A27) - 2014)), 0, 1) -> 0
A28: 43008.135 | B28: 17-2606 | C28: P034 | D28: 1 | E28: 114 | F28: =IF(E28="",_xlfn.XLOOKUP(C28,'Price Averages'!$D$4:$D$103,'Price Averages'!$E$4:$E$103, "FALSE"), E28) -> 114 | G28: 57 | H28: =IF(G28="", _xlfn.XLOOKUP(C28, 'Cost Averages'!$D$4:$D$103,'Cost Averages'!$E$4:$E$103, "FALSE"),G28) -> 57 | I28: =D28*F28 -> 114 | J28: =D28*H28 -> 57 | K28: =I28-J28 -> 57 | L28: Neither | M28: CT-3471 | N28: Creative & Technology | O28: 13.537351 | P28: =CHAR(64+(YEAR(A28)-2014)) -> C | Q28: =YEAR(A28) -> 2017 | R28: =IF(P28=CHAR(64 + (YEAR(A28) - 2014)), 0, 1) -> 0
A29: 42990.559 | B29: 17-3371 | C29: P063 | D29: 1 | E29: 261 | F29: =IF(E29="",_xlfn.XLOOKUP(C29,'Price Averages'!$D$4:$D$103,'Price Averages'!$E$4:$E$103, "FALSE"), E29) -> 261 | H29: =IF(G29="", _xlfn.XLOOKUP(C29, 'Cost Averages'!$D$4:$D$103,'Cost Averages'!$E$4:$E$103, "FALSE"),G29) -> 87 | I29: =D29*F29 -> 261 | J29: =D29*H29 -> 87 | K29: =I29-J29 -> 174 | L29: Satisfied | M29: HS-7291 | N29: Healthcare & Safety | O29: 10.42743 | P29: =CHAR(64+(YEAR(A29)-2014)) -> C | Q29: =YEAR(A29) -> 2017 | R29: =IF(P29=CHAR(64 + (YEAR(A29) - 2014)), 0, 1) -> 0
A30: 43028.202 | B30: 17-3360 | C30: P090 | D30: 1 | E30: 57 | F30: =IF(E30="",_xlfn.XLOOKUP(C30,'Price Averages'!$D$4:$D$103,'Price Averages'!$E$4:$E$103, "FALSE"), E30) -> 57 | G30: 19 | H30: =IF(G30="", _xlfn.XLOOKUP(C30, 'Cost Averages'!$D$4:$D$103,'Cost Averages'!$E$4:$E$103, "FALSE"),G30) -> 19 | I30: =D30*F30 -> 57 | J30: =D30*H30 -> 19 | K30: =I30-J30 -> 38 | L30: Satisfied | M30: HS-7827 | N30: Healthcare & Safety | O30: 9.3014286 | P30: =CHAR(64+(YEAR(A30)-2014)) -> C | Q30: =YEAR(A30) -> 2017 | R30: =IF(P30=CHAR(64 + (YEAR(A30) - 2014)), 0, 1) -> 0
A31: 42947.152 | B31: 17-3225 | C31: P100 | D31: 1 | E31: 46 | F31: =IF(E31="",_xlfn.XLOOKUP(C31,'Price Averages'!$D$4:$D$103,'Price Averages'!$E$4:$E$103, "FALSE"), E31) -> 46 | G31: 23 | H31: =IF(G31="", _xlfn.XLOOKUP(C31, 'Cost Averages'!$D$4:$D$103,'Cost Averages'!$E$4:$E$103, "FALSE"),G31) -> 23 | I31: =D31*F31 -> 46 | J31: =D31*H31 -> 23 | K31: =I31-J31 -> 23 | L31: Neither | M31: EE-40 | N31: Education | O31: 12.396052 | P31: =CHAR(64+(YEAR(A31)-2014)) -> C | Q31: =YEAR(A31) -> 2017 | R31: =IF(P31=CHAR(64 + (YEAR(A31) - 2014)), 0, 1) -> 0
A32: 42799.219 | B32: 17-1285 | C32: P011 | D32: 2 | E32: 264 | F32: =IF(E32="",_xlfn.XLOOKUP(C32,'Price Averages'!$D$4:$D$103,'Price Averages'!$E$4:$E$103, "FALSE"), E32) -> 264 | G32: 88 | H32: =IF(G32="", _xlfn.XLOOKUP(C32, 'Cost Averages'!$D$4:$D$103,'Cost Averages'!$E$4:$E$103, "FALSE"),G32) -> 88 | I32: =D32*F32 -> 528 | J32: =D32*H32 -> 176 | K32: =I32-J32 -> 352 | L32: Satisfied | M32: CP-2251 | N32: Corporate & Professional | O32: 11.003497 | P32: =CHAR(64+(YEAR(A32)-2014)) -> C | Q32: =YEAR(A32) -> 2017 | R32: =IF(P32=CHAR(64 + (YEAR(A32) - 2014)), 0, 1) -> 0
A33: 42889.125 | B33: 17-4153 | C33: P027 | D33: 2 | E33: 140 | F33: =IF(E33="",_xlfn.XLOOKUP(C33,'Price Averages'!$D$4:$D$103,'Price Averages'!$E$4:$E$103, "FALSE"), E33) -> 140 | G33: 70 | H33: =IF(G33="", _xlfn.XLOOKUP(C33, 'Cost Averages'!$D$4:$D$103,'Cost Averages'!$E$4:$E$103, "FALSE"),G33) -> 70 | I33: =D33*F33 -> 280 | J33: =D33*H33 -> 140 | K33: =I33-J33 -> 140 | L33: Dissatisfied | M33: CT-3920 | N33: Creative & Technology | O33: 14.661477 | P33: =CHAR(64+(YEAR(A33)-2014)) -> C | Q33: =YEAR(A33) -> 2017 | R33: =IF(P33=CHAR(64 + (YEAR(A33) - 2014)), 0, 1) -> 0
A34: 42968.905 | B34: 17-3578 | C34: P040 | D34: 2 | E34: 160 | F34: =IF(E34="",_xlfn.XLOOKUP(C34,'Price Averages'!$D$4:$D$103,'Price Averages'!$E$4:$E$103, "FALSE"), E34) -> 160 | G34: 80 | H34: =IF(G34="", _xlfn.XLOOKUP(C34, 'Cost Averages'!$D$4:$D$103,'Cost Averages'!$E$4:$E$103, "FALSE"),G34) -> 80 | I34: =D34*F34 -> 320 | J34: =D34*H34 -> 160 | K34: =I34-J34 -> 160 | L34: Neither | M34: FE-6631 | N34: Facilities & Services | O34: 8.1352386 | P34: =CHAR(64+(YEAR(A34)-2014)) -> C | Q34: =YEAR(A34) -> 2017 | R34: =IF(P34=CHAR(64 + (YEAR(A34) - 2014)), 0, 1) -> 0
A35: 43066.994 | B35: 17-2601 | C35: P048 | D35: 2 | F35: =IF(E35="",_xlfn.XLOOKUP(C35,'Price Averages'!$D$4:$D$103,'Price Averages'!$E$4:$E$103, "FALSE"), E35) -> 252 | H35: =IF(G35="", _xlfn.XLOOKUP(C35, 'Cost Averages'!$D$4:$D$103,'Cost Averages'!$E$4:$E$103, "FALSE"),G35) -> 63 | I35: =D35*F35 -> 504 | J35: =D35*H35 -> 126 | K35: =I35-J35 -> 378 | L35: Satisfied | M35: EE-4649 | N35: Education | O35: 13.392447 | P35: =CHAR(64+(YEAR(A35)-2014)) -> C | Q35: =YEAR(A35) -> 2017 | R35: =IF(P35=CHAR(64 + (YEAR(A35) - 2014)), 0, 1) -> 0
A36: 43038.144 | B36: 17-1307 | C36: P088 | D36: 2 | E36: 192 | F36: =IF(E36="",_xlfn.XLOOKUP(C36,'Price Averages'!$D$4:$D$103,'Price Averages'!$E$4:$E$103, "FALSE"), E36) -> 192 | G36: 96 | H36: =IF(G36="", _xlfn.XLOOKUP(C36, 'Cost Averages'!$D$4:$D$103,'Cost Averages'!$E$4:$E$103, "FALSE"),G36) -> 96 | I36: =D36*F36 -> 384 | J36: =D36*H36 -> 192 | K36: =I36-J36 -> 192 | L36: Neither | M36: CT-3796 | N36: Creative & Technology | O36: 15.207986 | P36: =CHAR(64+(YEAR(A36)-2014)) -> C | Q36: =YEAR(A36) -> 2017 | R36: =IF(P36=CHAR(64 + (YEAR(A36) - 2014)), 0, 1) -> 0
A37: 43072.093 | B37: 17-2741 | C37: P013 | D37: 3 | F37: =IF(E37="",_xlfn.XLOOKUP(C37,'Price Averages'!$D$4:$D$103,'Price Averages'!$E$4:$E$103, "FALSE"), E37) -> 58 | G37: 29 | H37: =IF(G37="", _xlfn.XLOOKUP(C37, 'Cost Averages'!$D$4:$D$103,'Cost Averages'!$E$4:$E$103, "FALSE"),G37) -> 29 | I37: =D37*F37 -> 174 | J37: =D37*H37 -> 87 | K37: =I37-J37 -> 87 | L37: Satisfied | M37: EE-4361 | N37: Education | O37: 14.760829 | P37: =CHAR(64+(YEAR(A37)-2014)) -> C | Q37: =YEAR(A37) -> 2017 | R37: =IF(P37=CHAR(64 + (YEAR(A37) - 2014)), 0, 1) -> 0
A38: 43007.042 | B38: 17-1266 | C38: P029 | D38: 3 | F38: =IF(E38="",_xlfn.XLOOKUP(C38,'Price Averages'!$D$4:$D$103,'Price Averages'!$E$4:$E$103, "FALSE"), E38) -> 300 | G38: 75 | H38: =IF(G38="", _xlfn.XLOOKUP(C38, 'Cost Averages'!$D$4:$D$103,'Cost Averages'!$E$4:$E$103, "FALSE"),G38) -> 75 | I38: =D38*F38 -> 900 | J38: =D38*H38 -> 225 | K38: =I38-J38 -> 675 | L38: Dissatisfied | M38: CT-3955 | N38: Creative & Technology | O38: 11.130819 | P38: =CHAR(64+(YEAR(A38)-2014)) -> C | Q38: =YEAR(A38) -> 2017 | R38: =IF(P38=CHAR(64 + (YEAR(A38) - 2014)), 0, 1) -> 0
A39: 43074.481 | B39: 17-4852 | C39: P034 | D39: 3 | F39: =IF(E39="",_xlfn.XLOOKUP(C39,'Price Averages'!$D$4:$D$103,'Price Averages'!$E$4:$E$103, "FALSE"), E39) -> 114 | G39: 57 | H39: =IF(G39="", _xlfn.XLOOKUP(C39, 'Cost Averages'!$D$4:$D$103,'Cost Averages'!$E$4:$E$103, "FALSE"),G39) -> 57 | I39: =D39*F39 -> 342 | J39: =D39*H39 -> 171 | K39: =I39-J39 -> 171 | L39: Satisfied | M39: EE-4140 | N39: Education | O39: 11.710936 | P39: =CHAR(64+(YEAR(A39)-2014)) -> C | Q39: =YEAR(A39) -> 2017 | R39: =IF(P39=CHAR(64 + (YEAR(A39) - 2014)), 0, 1) -> 0
A40: 43069.61 | B40: 17-3345 | C40: P064 | D40: 3 | E40: 231 | F40: =IF(E40="",_xlfn.XLOOKUP(C40,'Price Averages'!$D$4:$D$103,'Price Averages'!$E$4:$E$103, "FALSE"), E40) -> 231 | G40: 77 | H40: =IF(G40="", _xlfn.XLOOKUP(C40, 'Cost Averages'!$D$4:$D$103,'Cost Averages'!$E$4:$E$103, "FALSE"),G40) -> 77 | I40: =D40*F40 -> 693 | J40: =D40*H40 -> 231 | K40: =I40-J40 -> 462 | L40: Dissatisfied | M40: CG-142 | N40: Community & Government | O40: 14.412866 | P40: =CHAR(64+(YEAR(A40)-2014)) -> C | Q40: =YEAR(A40) -> 2017 | R40: =IF(P40=CHAR(64 + (YEAR(A40) - 2014)), 0, 1) -> 0
...

Sheet Stats Testing
B6: Profits
B7: A | C7: B | D7: C | E7: D | F7: E | G7: F | H7: G | I7: H | J7: I | K7: J | L7: K | O7: t-Test: Two-Sample Assuming Unequal Variances | S7: t-Test: Two-Sample Assuming Unequal Variances
B8: 80 | C8: 154 | D8: 170 | E8: 150 | F8: 150 | G8: 108 | H8: 57 | I8: 176 | J8: 210 | K8: 63 | L8: 540 | O8: Not Significant | S8: Not Significant
B9: 2160 | C9: 38 | D9: 57 | E9: 90 | F9: 55 | G9: 126 | H9: 57 | I9: 15 | J9: 267 | K9: 720 | L9: 400 | P9: A = 2015 | Q9: B = 2016 | T9: B = 2016 | U9: C = 2017
B10: 1701 | C10: 90 | D10: 174 | E10: 231 | F10: 90 | G10: 19 | H10: 108 | I10: 210 | J10: 17 | K10: 384 | O10: Mean | P10: 1448 | Q10: 1216.9474 | S10: Mean | T10: 1216.9474 | U10: 1193.6765
B11: 949 | C11: 115 | D11: 38 | E11: 138 | F11: 135 | G11: 88 | H11: 29 | I11: 70 | J11: 240 | K11: 1170 | O11: Variance | P11: 677092.4 | Q11: 1059982.7 | S11: Variance | T11: 1059982.7 | U11: 1261190.3
B12: 2278 | C12: 900 | D12: 23 | E12: 84 | F12: 102 | G12: 88 | H12: 83 | I12: 225 | J12: 264 | K12: 495 | O12: Observations | P12: 6 | Q12: 19 | S12: Observations | T12: 19 | U12: 102
B13: 1520 | C13: 736 | D13: 352 | E13: 80 | F13: 140 | G13: 55 | H13: 55 | I13: 73 | J13: 216 | K13: 282 | O13: Hypothesized Mean Difference | P13: 0 | S13: Hypothesized Mean Difference | T13: 0
C14: 2136 | D14: 140 | E14: 180 | F14: 78 | G14: 54 | H14: 54 | I14: 57 | J14: 450 | K14: 672 | O14: df | P14: 10 | S14: df | T14: 27
C15: 2430 | D15: 160 | E15: 25 | F15: 54 | G15: 54 | H15: 135 | I15: 96 | J15: 72 | K15: 1408 | O15: t Stat | P15: 0.56264453 | S15: t Stat | T15: 0.089139479
C16: 2640 | D16: 378 | E16: 276 | F16: 73 | G16: 138 | H16: 135 | I16: 80 | J16: 528 | K16: 2646 | O16: P(T<=t) one-tail | P16: 0.29303422 | S16: P(T<=t) one-tail | T16: 0.4648145
C17: 319 | D17: 192 | E17: 19 | F17: 73 | G17: 84 | H17: 135 | I17: 276 | J17: 102 | K17: 3150 | O17: t Critical one-tail | P17: 1.8124611 | S17: t Critical one-tail | T17: 1.7032884
C18: 1188 | D18: 87 | E18: 36 | F18: 38 | G18: 84 | H18: 102 | I18: 75 | J18: 420 | K18: 4488 | O18: P(T<=t) two-tail | P18: 0.58606844 | S18: P(T<=t) two-tail | T18: 0.92962899
C19: 1056 | D19: 675 | E19: 189 | F19: 210 | G19: 210 | H19: 84 | I19: 19 | J19: 297 | O19: t Critical two-tail | P19: 2.2281389 | S19: t Critical two-tail | T19: 2.0518305
C20: 3432 | D20: 171 | E20: 25 | F20: 80 | G20: 210 | H20: 84 | I20: 19 | J20: 280
C21: 1440 | D21: 462 | E21: 36 | F21: 160 | G21: 70 | H21: 210 | I21: 72 | J21: 228 | O21: t-Test: Two-Sample Assuming Unequal Variances | S21: t-Test: Two-Sample Assuming Unequal Variances
C22: 1280 | D22: 180 | E22: 267 | F22: 180 | G22: 54 | H22: 78 | I22: 264 | J22: 100 | O22: Not Significant | S22: Not Significant
C23: 2880 | D23: 297 | E23: 63 | F23: 25 | G23: 54 | H23: 78 | I23: 178 | J23: 384 | P23: C = 2017 | Q23: D = 2018 | T23: D = 2018 | U23: E = 2019
C24: 648 | D24: 144 | E24: 47 | F24: 276 | G24: 73 | H24: 225 | I24: 225 | J24: 184 | O24: Mean | P24: 1193.6765 | Q24: 1316.4048 | S24: Mean | T24: 1316.4048 | U24: 1169.192
C25: 1140 | D25: 750 | E25: 150 | F25: 276 | G25: 38 | H25: 38 | I25: 80 | J25: 690 | O25: Variance | P25: 1261190.3 | Q25: 1469973.5 | S25: Variance | T25: 1469973.5 | U25: 1174205.5
C26: 500 | D26: 400 | E26: 234 | F26: 75 | G26: 210 | H26: 57 | I26: 108 | J26: 1125 | O26: Observations | P26: 102 | Q26: 336 | S26: Observations | T26: 336 | U26: 750
D27: 1125 | E27: 51 | F27: 90 | G27: 180 | H27: 96 | I27: 150 | J27: 495 | O27: Hypothesized Mean Difference | P27: 0 | S27: Hypothesized Mean Difference | T27: 0
D28: 880 | E28: 216 | F28: 264 | G28: 25 | H28: 210 | I28: 38 | J28: 648 | O28: df | P28: 178 | S28: df | T28: 584
D29: 670 | E29: 252 | F29: 36 | G29: 75 | H29: 180 | I29: 96 | J29: 576 | O29: t Stat | P29: -0.94857796 | S29: t Stat | T29: 1.909998
D30: 756 | E30: 110 | F30: 36 | G30: 19 | H30: 108 | I30: 38 | J30: 644 | O30: P(T<=t) one-tail | P30: 0.17206068 | S30: P(T<=t) one-tail | T30: 0.028311514
D31: 900 | E31: 108 | F31: 36 | G31: 19 | H31: 25 | I31: 153 | J31: 1071 | O31: t Critical one-tail | P31: 1.6534591 | S31: t Critical one-tail | T31: 1.647467
D32: 648 | E32: 192 | F32: 176 | G32: 189 | H32: 276 | I32: 60 | J32: 768 | O32: P(T<=t) two-tail | P32: 0.34412137 | S32: P(T<=t) two-tail | T32: 0.056623029
D33: 1386 | E33: 360 | F33: 176 | G33: 267 | H33: 36 | I33: 96 | J33: 1200 | O33: t Critical two-tail | P33: 1.9733809 | S33: t Critical two-tail | T33: 1.9640344
D34: 438 | E34: 180 | F34: 25 | G34: 72 | H34: 264 | I34: 134 | J34: 810
D35: 480 | E35: 534 | F35: 17 | G35: 264 | H35: 264 | I35: 216 | J35: 720 | O35: t-Test: Two-Sample Assuming Unequal Variances | S35: t-Test: Two-Sample Assuming Unequal Variances
D36: 1044 | E36: 352 | F36: 108 | G36: 264 | H36: 25 | I36: 352 | J36: 153
D37: 150 | E37: 522 | F37: 225 | G37: 25 | H37: 189 | I37: 352 | J37: 423 | P37: E = 2019 | Q37: F = 2020 | T37: F = 2020 | U37: G = 2021
D38: 840 | E38: 522 | F38: 63 | G38: 96 | H38: 267 | I38: 110 | J38: 780 | O38: Mean | P38: 1169.192 | Q38: 1219.6756 | S38: Mean | T38: 1219.6756 | U38: 1215.0917
D39: 900 | E39: 216 | F39: 264 | G39: 36 | H39: 25 | I39: 180 | J39: 960 | O39: Variance | P39: 1174205.5 | Q39: 1247023.7 | S39: Variance | T39: 1247023.7 | U39: 1286281.9
D40: 150 | E40: 50 | F40: 216 | G40: 36 | H40: 108 | I40: 276 | J40: 1530 | O40: Observations | P40: 750 | Q40: 1153 | S40: Observations | T40: 1153 | U40: 905
D41: 528 | E41: 171 | F41: 216 | G41: 189 | H41: 225 | I41: 280 | J41: 2079 | O41: Hypothesized Mean Difference | P41: 0 | S41: Hypothesized Mean Difference | T41: 0
D42: 372 | E42: 264 | F42: 114 | G42: 189 | H42: 75 | I42: 450 | J42: 1540 | O42: df | P42: 1634 | S42: df | T42: 1927
D43: 576 | E43: 162 | F43: 38 | G43: 267 | H43: 75 | I43: 146 | J43: 1683 | O43: t Stat | P43: -0.98120767 | S43: t Stat | T43: 0.091626056
D44: 138 | E44: 99 | F44: 300 | G44: 267 | H44: 264 | I44: 92 | J44: 960 | O44: P(T<=t) one-tail | P44: 0.1633178 | S44: P(T<=t) one-tail | T44: 0.46350234
D45: 966 | E45: 138 | F45: 216 | G45: 267 | H45: 80 | I45: 76 | J45: 540 | O45: t Critical one-tail | P45: 1.6457867 | S45: t Critical one-tail | T45: 1.6456448
...

Sheet Project Work - Analysis Notes
B1: Exercise -Data | C1: Project Work
A2: Data Discovery and Exploration | B2: Specify the Question and scope the answer, Obtain the Data | C2: Price = Profit + Cost Which consecutive Years had significantly different Profits?
A3: Pre-Processing | B3: Data Summaries (Categorical, Numeric), Identification and Summarization of Data Issues (Null, Missing, Corrutped values,etc.), Feature Selection, Dimensionality Reduction, Normalization, Data Subsetting | C3: Data Issues Discovered Fiscal Dates from Order Dates, Profit by Order, Cost by Order Dimensional Reduction not necessary for analysis Normalization not necessary but Transormation is due to dollars compared to dollars Subsets by Year used in Analysis (Each Year is applied a Name A , B, and C)
A4: Data Mining | B4: Resolving Data Issues, Performing Analysis | C4: Data Corruption - Six Columns have corrupted data
A5: Post-Processing | B5: Statistical Testing, Significance Testing, Sampling of Instances, Hypothesis Testing | C5: T- Tests between Years for Profit across Years
A6: Information Development | B6: Analysis Outcomes, Data Review, Data Issue Summary, | C6: Test Results and Regression Summary Univariate Analysis for Profit and Cost for each Year, Bivariate Analysis for each year of Cost and Profit, Data Issues, Resolution Steps, and Effects of Resolution
A7: Outcome Communication | B7: Answering the Specific Questions, Report formation, and messaging | C7: Which onsecutive Years had significantly different Profits? Report Formation (Analysis Outcome Review) Messaging (2 Minute Talk about answer and julstificaiton - 175 words)

Sheet Data Dictionary
A1: Variables | B1: Data Type
A2: Order Date | B2: Interval | C2: Discrete
A3: Order Number | B3: Nominal | C3: Discrete
A4: Product | B4: Nominal | C4: Discrete
A5: Quantity | B5: Ratio | C5: Continuous
A6: Price Per Unit | B6: Ratio | C6: Continuous
A7: Cost per Unit | B7: Ratio | C7: Continuous
A8: Revenue | B8: Ratio | C8: Continuous
A9: Costs | B9: Ratio | C9: Continuous
A10: Profit | B10: Ratio | C10: Continuous
A11: Order Survey Response | B11: Ordinal | C11: Discrete
A12: Customer ID | B12: Nominal | C12: Discrete
A13: Customer Category | B13: Nominal | C13: Discrete
... A16: Subset | B16: Ordinal | C16: Discrete

Sheet Project Work - Data wrows
A1: Order Date | B1: Order Number | C1: Product | D1: Quantity | E1: Fixed Quantity | F1: Price Per Unit | G1: Fixed Price Per Unit | H1: Cost per Unit | I1: Fixed Cost Per Unit | J1: Revenue | K1: Costs | L1: Profit | M1: Order Survey Response | N1: Customer ID | O1: Customer Category | P1: Customer Tenure | Q1: Subset Label | R1: Subset | S1: Subset Check
A2: 42297.389 | B2: 15-3098 | C2: P031 | D2: 13 | E2: =IF(D2="", _xlfn.XLOOKUP(C2,'Median Quantity per product'!$D$4:$D$103,'Median Quantity per product'!$E$4:$E$103, "NA"),'Project Work - Data wrows'!D2) -> 13 | G2: =IF(F2="",_xlfn.XLOOKUP(C2,'Price Averages'!$D$4:$D$103,'Price Averages'!$E$4:$E$103, "FALSE"), F2) -> 146 | H2: 73 | I2: =IF(H2="", _xlfn.XLOOKUP(C2, 'Cost Averages'!$D$4:$D$103,'Cost Averages'!$E$4:$E$103, "FALSE"),H2) -> 73 | J2: =E2*G2 -> 1898 | K2: =E2*I2 -> 949 | L2: =J2-K2 -> 949 | M2: Neither | N2: HS-770 | O2: Healthcare & Safety | P2: 12.148237 | Q2: =CHAR(64+(YEAR(A2)-2014)) -> A | R2: =YEAR(A2) -> 2015 | S2: =IF(Q2=CHAR(64 + (YEAR(A2) - 2014)), 0, 1) -> 0
A3: 42258.411 | B3: 15-4254 | C3: P037 | D3: 1 | E3: =IF(D3="", _xlfn.XLOOKUP(C3,'Median Quantity per product'!$D$4:$D$103,'Median Quantity per product'!$E$4:$E$103, "NA"),'Project Work - Data wrows'!D3) -> 1 | F3: 160 | G3: =IF(F3="",_xlfn.XLOOKUP(C3,'Price Averages'!$D$4:$D$103,'Price Averages'!$E$4:$E$103, "FALSE"), F3) -> 160 | H3: 80 | I3: =IF(H3="", _xlfn.XLOOKUP(C3, 'Cost Averages'!$D$4:$D$103,'Cost Averages'!$E$4:$E$103, "FALSE"),H3) -> 80 | J3: =E3*G3 -> 160 | K3: =E3*I3 -> 80 | L3: =J3-K3 -> 80 | M3: Neither | N3: HS-7862 | O3: Healthcare & Safety | P3: 14.423323 | Q3: =CHAR(64+(YEAR(A3)-2014)) -> A | R3: =YEAR(A3) -> 2015 | S3: =IF(Q3=CHAR(64 + (YEAR(A3) - 2014)), 0, 1) -> 0
A4: 42178.711 | B4: 15-2073 | C4: P055 | D4: 8 | E4: =IF(D4="", _xlfn.XLOOKUP(C4,'Median Quantity per product'!$D$4:$D$103,'Median Quantity per product'!$E$4:$E$103, "NA"),'Project Work - Data wrows'!D4) -> 8 | F4: 360 | G4: =IF(F4="",_xlfn.XLOOKUP(C4,'Price Averages'!$D$4:$D$103,'Price Averages'!$E$4:$E$103, "FALSE"), F4) -> 360 | H4: 90 | I4: =IF(H4="", _xlfn.XLOOKUP(C4, 'Cost Averages'!$D$4:$D$103,'Cost Averages'!$E$4:$E$103, "FALSE"),H4) -> 90 | J4: =E4*G4 -> 2880 | K4: =E4*I4 -> 720 | L4: =J4-K4 -> 2160 | M4: Neither | N4: CP-2960 | O4: Corporate & Professional | P4: 13.062293 | Q4: =CHAR(64+(YEAR(A4)-2014)) -> A | R4: =YEAR(A4) -> 2015 | S4: =IF(Q4=CHAR(64 + (YEAR(A4) - 2014)), 0, 1) -> 0
A5: 42368.549 | B5: 15-3490 | C5: P057 | D5: 9 | E5: =IF(D5="", _xlfn.XLOOKUP(C5,'Median Quantity per product'!$D$4:$D$103,'Median Quantity per product'!$E$4:$E$103, "NA"),'Project Work - Data wrows'!D5) -> 9 | F5: 252 | G5: =IF(F5="",_xlfn.XLOOKUP(C5,'Price Averages'!$D$4:$D$103,'Price Averages'!$E$4:$E$103, "FALSE"), F5) -> 252 | H5: 63 | I5: =IF(H5="", _xlfn.XLOOKUP(C5, 'Cost Averages'!$D$4:$D$103,'Cost Averages'!$E$4:$E$103, "FALSE"),H5) -> 63 | J5: =E5*G5 -> 2268 | K5: =E5*I5 -> 567 | L5: =J5-K5 -> 1701 | M5: Satisfied | N5: CT-3606 | O5: Creative & Technology | P5: 12.173452 | Q5: =CHAR(64+(YEAR(A5)-2014)) -> A | R5: =YEAR(A5) -> 2015 | S5: =IF(Q5=CHAR(64 + (YEAR(A5) - 2014)), 0, 1) -> 0
A6: 42216.891 | B6: 15-4617 | C6: P075 | D6: 19 | E6: =IF(D6="", _xlfn.XLOOKUP(C6,'Median Quantity per product'!$D$4:$D$103,'Median Quantity per product'!$E$4:$E$103, "NA"),'Project Work - Data wrows'!D6) -> 19 | F6: 160 | G6: =IF(F6="",_xlfn.XLOOKUP(C6,'Price Averages'!$D$4:$D$103,'Price Averages'!$E$4:$E$103, "FALSE"), F6) -> 160 | H6: 80 | I6: =IF(H6="", _xlfn.XLOOKUP(C6, 'Cost Averages'!$D$4:$D$103,'Cost Averages'!$E$4:$E$103, "FALSE"),H6) -> 80 | J6: =E6*G6 -> 3040 | K6: =E6*I6 -> 1520 | L6: =J6-K6 -> 1520 | M6: Neither | N6: EE-4917 | O6: Education | P6: 11.756375 | Q6: =CHAR(64+(YEAR(A6)-2014)) -> A | R6: =YEAR(A6) -> 2015 | S6: =IF(Q6=CHAR(64 + (YEAR(A6) - 2014)), 0, 1) -> 0
A7: 42322.453 | B7: 15-3015 | C7: P098 | D7: 17 | E7: =IF(D7="", _xlfn.XLOOKUP(C7,'Median Quantity per product'!$D$4:$D$103,'Median Quantity per product'!$E$4:$E$103, "NA"),'Project Work - Data wrows'!D7) -> 17 | F7: 201 | G7: =IF(F7="",_xlfn.XLOOKUP(C7,'Price Averages'!$D$4:$D$103,'Price Averages'!$E$4:$E$103, "FALSE"), F7) -> 201 | H7: 67 | I7: =IF(H7="", _xlfn.XLOOKUP(C7, 'Cost Averages'!$D$4:$D$103,'Cost Averages'!$E$4:$E$103, "FALSE"),H7) -> 67 | J7: =E7*G7 -> 3417 | K7: =E7*I7 -> 1139 | L7: =J7-K7 -> 2278 | M7: Satisfied | N7: EE-4613 | O7: Education | P7: 15.26855 | Q7: =CHAR(64+(YEAR(A7)-2014)) -> A | R7: =YEAR(A7) -> 2015 | S7: =IF(Q7=CHAR(64 + (YEAR(A7) - 2014)), 0, 1) -> 0
A8: 42641.299 | B8: 16-1896 | C8: P005 | D8: 20 | E8: =IF(D8="", _xlfn.XLOOKUP(C8,'Median Quantity per product'!$D$4:$D$103,'Median Quantity per product'!$E$4:$E$103, "NA"),'Project Work - Data wrows'!D8) -> 20 | G8: =IF(F8="",_xlfn.XLOOKUP(C8,'Price Averages'!$D$4:$D$103,'Price Averages'!$E$4:$E$103, "FALSE"), F8) -> 76 | H8: 19 | I8: =IF(H8="", _xlfn.XLOOKUP(C8, 'Cost Averages'!$D$4:$D$103,'Cost Averages'!$E$4:$E$103, "FALSE"),H8) -> 19 | J8: =E8*G8 -> 1520 | K8: =E8*I8 -> 380 | L8: =J8-K8 -> 1140 | M8: Neither | N8: CT-3174 | O8: Creative & Technology | P8: 15.187892 | Q8: =CHAR(64+(YEAR(A8)-2014)) -> B | R8: =YEAR(A8) -> 2016 | S8: =IF(Q8=CHAR(64 + (YEAR(A8) - 2014)), 0, 1) -> 0
A9: 42673.243 | B9: 16-1836 | C9: P006 | D9: 2 | E9: =IF(D9="", _xlfn.XLOOKUP(C9,'Median Quantity per product'!$D$4:$D$103,'Median Quantity per product'!$E$4:$E$103, "NA"),'Project Work - Data wrows'!D9) -> 2 | G9: =IF(F9="",_xlfn.XLOOKUP(C9,'Price Averages'!$D$4:$D$103,'Price Averages'!$E$4:$E$103, "FALSE"), F9) -> 38 | H9: 19 | I9: =IF(H9="", _xlfn.XLOOKUP(C9, 'Cost Averages'!$D$4:$D$103,'Cost Averages'!$E$4:$E$103, "FALSE"),H9) -> 19 | J9: =E9*G9 -> 76 | K9: =E9*I9 -> 38 | L9: =J9-K9 -> 38 | M9: Neither | N9: CG-1672 | O9: Community & Government | P9: 11.655356 | Q9: =CHAR(64+(YEAR(A9)-2014)) -> B | R9: =YEAR(A9) -> 2016 | S9: =IF(Q9=CHAR(64 + (YEAR(A9) - 2014)), 0, 1) -> 0
A10: 42695.685 | B10: 16-4606 | C10: P008 | D10: 6 | E10: =IF(D10="", _xlfn.XLOOKUP(C10,'Median Quantity per product'!$D$4:$D$103,'Median Quantity per product'!$E$4:$E$103, "NA"),'Project Work - Data wrows'!D10) -> 6 | F10: 225 | G10: =IF(F10="",_xlfn.XLOOKUP(C10,'Price Averages'!$D$4:$D$103,'Price Averages'!$E$4:$E$103, "FALSE"), F10) -> 225 | H10: 75 | I10: =IF(H10="", _xlfn.XLOOKUP(C10, 'Cost Averages'!$D$4:$D$103,'Cost Averages'!$E$4:$E$103, "FALSE"),H10) -> 75 | J10: =E10*G10 -> 1350 | K10: =E10*I10 -> 450 | L10: =J10-K10 -> 900 | M10: Neither | N10: SR-930 | O10: Sports & Recreation | P10: 14.690199 | Q10: =CHAR(64+(YEAR(A10)-2014)) -> B | R10: =YEAR(A10) -> 2016 | S10: =IF(Q10=CHAR(64 + (YEAR(A10) - 2014)), 0, 1) -> 0
A11: 42681.511 | B11: 16-3455 | C11: P013 | D11: 11 | E11: =IF(D11="", _xlfn.XLOOKUP(C11,'Median Quantity per product'!$D$4:$D$103,'Median Quantity per product'!$E$4:$E$103, "NA"),'Project Work - Data wrows'!D11) -> 11 | F11: 58 | G11: =IF(F11="",_xlfn.XLOOKUP(C11,'Price Averages'!$D$4:$D$103,'Price Averages'!$E$4:$E$103, "FALSE"), F11) -> 58 | I11: =IF(H11="", _xlfn.XLOOKUP(C11, 'Cost Averages'!$D$4:$D$103,'Cost Averages'!$E$4:$E$103, "FALSE"),H11) -> 29 | J11: =E11*G11 -> 638 | K11: =E11*I11 -> 319 | L11: =J11-K11 -> 319 | M11: Neither | N11: EE-450 | O11: Education | P11: 8.3272838 | Q11: =CHAR(64+(YEAR(A11)-2014)) -> B | R11: =YEAR(A11) -> 2016 | S11: =IF(Q11=CHAR(64 + (YEAR(A11) - 2014)), 0, 1) -> 0
A12: 42709.937 | B12: 16-4839 | C12: P017 | D12: 16 | E12: =IF(D12="", _xlfn.XLOOKUP(C12,'Median Quantity per product'!$D$4:$D$103,'Median Quantity per product'!$E$4:$E$103, "NA"),'Project Work - Data wrows'!D12) -> 16 | F12: 120 | G12: =IF(F12="",_xlfn.XLOOKUP(C12,'Price Averages'!$D$4:$D$103,'Price Averages'!$E$4:$E$103, "FALSE"), F12) -> 120 | H12: 30 | I12: =IF(H12="", _xlfn.XLOOKUP(C12, 'Cost Averages'!$D$4:$D$103,'Cost Averages'!$E$4:$E$103, "FALSE"),H12) -> 30 | J12: =E12*G12 -> 1920 | K12: =E12*I12 -> 480 | L12: =J12-K12 -> 1440 | M12: Satisfied | N12: CP-2926 | O12: Corporate & Professional | P12: 8.1743378 | Q12: =CHAR(64+(YEAR(A12)-2014)) -> B | R12: =YEAR(A12) -> 2016 | S12: =IF(Q12=CHAR(64 + (YEAR(A12) - 2014)), 0, 1) -> 0
A13: 42686.704 | B13: 16-4049 | C13: P038 | D13: 18 | E13: =IF(D13="", _xlfn.XLOOKUP(C13,'Median Quantity per product'!$D$4:$D$103,'Median Quantity per product'!$E$4:$E$103, "NA"),'Project Work - Data wrows'!D13) -> 18 | F13: 240 | G13: =IF(F13="",_xlfn.XLOOKUP(C13,'Price Averages'!$D$4:$D$103,'Price Averages'!$E$4:$E$103, "FALSE"), F13) -> 240 | H13: 80 | I13: =IF(H13="", _xlfn.XLOOKUP(C13, 'Cost Averages'!$D$4:$D$103,'Cost Averages'!$E$4:$E$103, "FALSE"),H13) -> 80 | J13: =E13*G13 -> 4320 | K13: =E13*I13 -> 1440 | L13: =J13-K13 -> 2880 | M13: Neither | N13: SR-9468 | O13: Sports & Recreation | P13: 10.010333 | Q13: =CHAR(64+(YEAR(A13)-2014)) -> B | R13: =YEAR(A13) -> 2016 | S13: =IF(Q13=CHAR(64 + (YEAR(A13) - 2014)), 0, 1) -> 0
A14: 42676.558 | B14: 16-1558 | C14: P040 | D14: 16 | E14: =IF(D14="", _xlfn.XLOOKUP(C14,'Median Quantity per product'!$D$4:$D$103,'Median Quantity per product'!$E$4:$E$103, "NA"),'Project Work - Data wrows'!D14) -> 16 | F14: 160 | G14: =IF(F14="",_xlfn.XLOOKUP(C14,'Price Averages'!$D$4:$D$103,'Price Averages'!$E$4:$E$103, "FALSE"), F14) -> 160 | H14: 80 | I14: =IF(H14="", _xlfn.XLOOKUP(C14, 'Cost Averages'!$D$4:$D$103,'Cost Averages'!$E$4:$E$103, "FALSE"),H14) -> 80 | J14: =E14*G14 -> 2560 | K14: =E14*I14 -> 1280 | L14: =J14-K14 -> 1280 | M14: Neither | N14: FE-6981 | O14: Facilities & Services | P14: 10.517826 | Q14: =CHAR(64+(YEAR(A14)-2014)) -> B | R14: =YEAR(A14) -> 2016 | S14: =IF(Q14=CHAR(64 + (YEAR(A14) - 2014)), 0, 1) -> 0
A15: 42693.272 | B15: 16-2390 | C15: P043 | D15: 8 | E15: =IF(D15="", _xlfn.XLOOKUP(C15,'Median Quantity per product'!$D$4:$D$103,'Median Quantity per product'!$E$4:$E$103, "NA"),'Project Work - Data wrows'!D15) -> 8 | F15: 184 | G15: =IF(F15="",_xlfn.XLOOKUP(C15,'Price Averages'!$D$4:$D$103,'Price Averages'!$E$4:$E$103, "FALSE"), F15) -> 184 | H15: 92 | I15: =IF(H15="", _xlfn.XLOOKUP(C15, 'Cost Averages'!$D$4:$D$103,'Cost Averages'!$E$4:$E$103, "FALSE"),H15) -> 92 | J15: =E15*G15 -> 1472 | K15: =E15*I15 -> 736 | L15: =J15-K15 -> 736 | M15: Neither | N15: HS-712 | O15: Healthcare & Safety | P15: 10.428287 | Q15: =CHAR(64+(YEAR(A15)-2014)) -> B | R15: =YEAR(A15) -> 2016 | S15: =IF(Q15=CHAR(64 + (YEAR(A15) - 2014)), 0, 1) -> 0
A16: 42720.868 | B16: 16-4872 | C16: P055 | D16: 9 | E16: =IF(D16="", _xlfn.XLOOKUP(C16,'Median Quantity per product'!$D$4:$D$103,'Median Quantity per product'!$E$4:$E$103, "NA"),'Project Work - Data wrows'!D16) -> 9 | G16: =IF(F16="",_xlfn.XLOOKUP(C16,'Price Averages'!$D$4:$D$103,'Price Averages'!$E$4:$E$103, "FALSE"), F16) -> 360 | H16: 90 | I16: =IF(H16="", _xlfn.XLOOKUP(C16, 'Cost Averages'!$D$4:$D$103,'Cost Averages'!$E$4:$E$103, "FALSE"),H16) -> 90 | J16: =E16*G16 -> 3240 | K16: =E16*I16 -> 810 | L16: =J16-K16 -> 2430 | M16: Satisfied | N16: SR-9808 | O16: Sports & Recreation | P16: 10.816866 | Q16: =CHAR(64+(YEAR(A16)-2014)) -> B | R16: =YEAR(A16) -> 2016 | S16: =IF(Q16=CHAR(64 + (YEAR(A16) - 2014)), 0, 1) -> 0
A17: 42485.261 | B17: 16-3871 | C17: P056 | D17: 18 | E17: =IF(D17="", _xlfn.XLOOKUP(C17,'Median Quantity per product'!$D$4:$D$103,'Median Quantity per product'!$E$4:$E$103, "NA"),'Project Work - Data wrows'!D17) -> 18 | G17: =IF(F17="",_xlfn.XLOOKUP(C17,'Price Averages'!$D$4:$D$103,'Price Averages'!$E$4:$E$103, "FALSE"), F17) -> 72 | H17: 36 | I17: =IF(H17="", _xlfn.XLOOKUP(C17, 'Cost Averages'!$D$4:$D$103,'Cost Averages'!$E$4:$E$103, "FALSE"),H17) -> 36 | J17: =E17*G17 -> 1296 | K17: =E17*I17 -> 648 | L17: =J17-K17 -> 648 | M17: Dissatisfied | N17: CT-3881 | O17: Creative & Technology | P17: 13.459801 | Q17: =CHAR(64+(YEAR(A17)-2014)) -> B | R17: =YEAR(A17) -> 2016 | S17: =IF(Q17=CHAR(64 + (YEAR(A17) - 2014)), 0, 1) -> 0
A18: 42656.038 | B18: 16-1050 | C18: P058 | D18: 8 | E18: =IF(D18="", _xlfn.XLOOKUP(C18,'Median Quantity per product'!$D$4:$D$103,'Median Quantity per product'!$E$4:$E$103, "NA"),'Project Work - Data wrows'!D18) -> 8 | G18: =IF(F18="",_xlfn.XLOOKUP(C18,'Price Averages'!$D$4:$D$103,'Price Averages'!$E$4:$E$103, "FALSE"), F18) -> 356 | H18: 89 | I18: =IF(H18="", _xlfn.XLOOKUP(C18, 'Cost Averages'!$D$4:$D$103,'Cost Averages'!$E$4:$E$103, "FALSE"),H18) -> 89 | J18: =E18*G18 -> 2848 | K18: =E18*I18 -> 712 | L18: =J18-K18 -> 2136 | M18: Neither | N18: EE-4357 | O18: Education | P18: 13.466363 | Q18: =CHAR(64+(YEAR(A18)-2014)) -> B | R18: =YEAR(A18) -> 2016 | S18: =IF(Q18=CHAR(64 + (YEAR(A18) - 2014)), 0, 1) -> 0
A19: 42720.978 | B19: 16-1451 | C19: P064 | D19: 1 | E19: =IF(D19="", _xlfn.XLOOKUP(C19,'Median Quantity per product'!$D$4:$D$103,'Median Quantity per product'!$E$4:$E$103, "NA"),'Project Work - Data wrows'!D19) -> 1 | F19: 231 | G19: =IF(F19="",_xlfn.XLOOKUP(C19,'Price Averages'!$D$4:$D$103,'Price Averages'!$E$4:$E$103, "FALSE"), F19) -> 231 | H19: 77 | I19: =IF(H19="", _xlfn.XLOOKUP(C19, 'Cost Averages'!$D$4:$D$103,'Cost Averages'!$E$4:$E$103, "FALSE"),H19) -> 77 | J19: =E19*G19 -> 231 | K19: =E19*I19 -> 77 | L19: =J19-K19 -> 154 | M19: Neither | N19: CT-3498 | O19: Creative & Technology | P19: 10.588336 | Q19: =CHAR(64+(YEAR(A19)-2014)) -> B | R19: =YEAR(A19) -> 2016 | S19: =IF(Q19=CHAR(64 + (YEAR(A19) - 2014)), 0, 1) -> 0
A20: 42715.504 | B20: 16-1764 | C20: P065 | E20: =IF(D20="", _xlfn.XLOOKUP(C20,'Median Quantity per product'!$D$4:$D$103,'Median Quantity per product'!$E$4:$E$103, "NA"),'Project Work - Data wrows'!D20) -> 10 | F20: 50 | G20: =IF(F20="",_xlfn.XLOOKUP(C20,'Price Averages'!$D$4:$D$103,'Price Averages'!$E$4:$E$103, "FALSE"), F20) -> 50 | I20: =IF(H20="", _xlfn.XLOOKUP(C20, 'Cost Averages'!$D$4:$D$103,'Cost Averages'!$E$4:$E$103, "FALSE"),H20) -> 25 | J20: =E20*G20 -> 500 | K20: =E20*I20 -> 250 | L20: =J20-K20 -> 250 | M20: Neither | N20: CT-3439 | O20: Creative & Technology | P20: 7.897407 | Q20: =CHAR(64+(YEAR(A20)-2014)) -> B | R20: =YEAR(A20) -> 2016 | S20: =IF(Q20=CHAR(64 + (YEAR(A20) - 2014)), 0, 1) -> 0
A21: 42614.075 | B21: 16-2604 | C21: P067 | D21: 11 | E21: =IF(D21="", _xlfn.XLOOKUP(C21,'Median Quantity per product'!$D$4:$D$103,'Median Quantity per product'!$E$4:$E$103, "NA"),'Project Work - Data wrows'!D21) -> 11 | F21: 144 | G21: =IF(F21="",_xlfn.XLOOKUP(C21,'Price Averages'!$D$4:$D$103,'Price Averages'!$E$4:$E$103, "FALSE"), F21) -> 144 | H21: 36 | I21: =IF(H21="", _xlfn.XLOOKUP(C21, 'Cost Averages'!$D$4:$D$103,'Cost Averages'!$E$4:$E$103, "FALSE"),H21) -> 36 | J21: =E21*G21 -> 1584 | K21: =E21*I21 -> 396 | L21: =J21-K21 -> 1188 | M21: Satisfied | N21: CG-137 | O21: Community & Government | P21: 12.796588 | Q21: =CHAR(64+(YEAR(A21)-2014)) -> B | R21: =YEAR(A21) -> 2016 | S21: =IF(Q21=CHAR(64 + (YEAR(A21) - 2014)), 0, 1) -> 0
A22: 42615.366 | B22: 16-4442 | C22: P072 | D22: 12 | E22: =IF(D22="", _xlfn.XLOOKUP(C22,'Median Quantity per product'!$D$4:$D$103,'Median Quantity per product'!$E$4:$E$103, "NA"),'Project Work - Data wrows'!D22) -> 12 | F22: 132 | G22: =IF(F22="",_xlfn.XLOOKUP(C22,'Price Averages'!$D$4:$D$103,'Price Averages'!$E$4:$E$103, "FALSE"), F22) -> 132 | H22: 44 | I22: =IF(H22="", _xlfn.XLOOKUP(C22, 'Cost Averages'!$D$4:$D$103,'Cost Averages'!$E$4:$E$103, "FALSE"),H22) -> 44 | J22: =E22*G22 -> 1584 | K22: =E22*I22 -> 528 | L22: =J22-K22 -> 1056 | M22: Dissatisfied | N22: FE-6892 | O22: Facilities & Services | P22: 14.817898 | Q22: =CHAR(64+(YEAR(A22)-2014)) -> B | R22: =YEAR(A22) -> 2016 | S22: =IF(Q22=CHAR(64 + (YEAR(A22) - 2014)), 0, 1) -> 0
A23: 42476.479 | B23: 16-2216 | C23: P074 | D23: 10 | E23: =IF(D23="", _xlfn.XLOOKUP(C23,'Median Quantity per product'!$D$4:$D$103,'Median Quantity per product'!$E$4:$E$103, "NA"),'Project Work - Data wrows'!D23) -> 10 | F23: 352 | G23: =IF(F23="",_xlfn.XLOOKUP(C23,'Price Averages'!$D$4:$D$103,'Price Averages'!$E$4:$E$103, "FALSE"), F23) -> 352 | I23: =IF(H23="", _xlfn.XLOOKUP(C23, 'Cost Averages'!$D$4:$D$103,'Cost Averages'!$E$4:$E$103, "FALSE"),H23) -> 88 | J23: =E23*G23 -> 3520 | K23: =E23*I23 -> 880 | L23: =J23-K23 -> 2640 | M23: Dissatisfied | N23: HS-7291 | O23: Healthcare & Safety | P23: 10.42743 | Q23: =CHAR(64+(YEAR(A23)-2014)) -> B | R23: =YEAR(A23) -> 2016 | S23: =IF(Q23=CHAR(64 + (YEAR(A23) - 2014)), 0, 1) -> 0
A24: 42614.684 | B24: 16-1985 | C24: P074 | D24: 13 | E24: =IF(D24="", _xlfn.XLOOKUP(C24,'Median Quantity per product'!$D$4:$D$103,'Median Quantity per product'!$E$4:$E$103, "NA"),'Project Work - Data wrows'!D24) -> 13 | F24: 352 | G24: =IF(F24="",_xlfn.XLOOKUP(C24,'Price Averages'!$D$4:$D$103,'Price Averages'!$E$4:$E$103, "FALSE"), F24) -> 352 | H24: 88 | I24: =IF(H24="", _xlfn.XLOOKUP(C24, 'Cost Averages'!$D$4:$D$103,'Cost Averages'!$E$4:$E$103, "FALSE"),H24) -> 88 | J24: =E24*G24 -> 4576 | K24: =E24*I24 -> 1144 | L24: =J24-K24 -> 3432 | M24: Satisfied | N24: CP-2325 | O24: Corporate & Professional | P24: 11.701919 | Q24: =CHAR(64+(YEAR(A24)-2014)) -> B | R24: =YEAR(A24) -> 2016 | S24: =IF(Q24=CHAR(64 + (YEAR(A24) - 2014)), 0, 1) -> 0
A25: 42720.244 | B25: 16-1417 | C25: P081 | D25: 20 | E25: =IF(D25="", _xlfn.XLOOKUP(C25,'Median Quantity per product'!$D$4:$D$103,'Median Quantity per product'!$E$4:$E$103, "NA"),'Project Work - Data wrows'!D25) -> 20 | F25: 50 | G25: =IF(F25="",_xlfn.XLOOKUP(C25,'Price Averages'!$D$4:$D$103,'Price Averages'!$E$4:$E$103, "FALSE"), F25) -> 50 | I25: =IF(H25="", _xlfn.XLOOKUP(C25, 'Cost Averages'!$D$4:$D$103,'Cost Averages'!$E$4:$E$103, "FALSE"),H25) -> 25 | J25: =E25*G25 -> 1000 | K25: =E25*I25 -> 500 | L25: =J25-K25 -> 500 | M25: Neither | N25: CP-2629 | O25: Corporate & Professional | P25: 10.411813 | Q25: =CHAR(64+(YEAR(A25)-2014)) -> B | R25: =YEAR(A25) -> 2016 | S25: =IF(Q25=CHAR(64 + (YEAR(A25) - 2014)), 0, 1) -> 0
A26: 42673.971 | B26: 16-3460 | C26: P083 | D26: 2 | E26: =IF(D26="", _xlfn.XLOOKUP(C26,'Median Quantity per product'!$D$4:$D$103,'Median Quantity per product'!$E$4:$E$103, "NA"),'Project Work - Data wrows'!D26) -> 2 | F26: 90 | G26: =IF(F26="",_xlfn.XLOOKUP(C26,'Price Averages'!$D$4:$D$103,'Price Averages'!$E$4:$E$103, "FALSE"), F26) -> 90 | I26: =IF(H26="", _xlfn.XLOOKUP(C26, 'Cost Averages'!$D$4:$D$103,'Cost Averages'!$E$4:$E$103, "FALSE"),H26) -> 45 | J26: =E26*G26 -> 180 | K26: =E26*I26 -> 90 | L26: =J26-K26 -> 90 | M26: Satisfied | N26: CT-3920 | O26: Creative & Technology | P26: 14.661477 | Q26: =CHAR(64+(YEAR(A26)-2014)) -> B | R26: =YEAR(A26) -> 2016 | S26: =IF(Q26=CHAR(64 + (YEAR(A26) - 2014)), 0, 1) -> 0
A27: 42472.852 | B27: 16-2269 | C27: P088 | E27: =IF(D27="", _xlfn.XLOOKUP(C27,'Median Quantity per product'!$D$4:$D$103,'Median Quantity per product'!$E$4:$E$103, "NA"),'Project Work - Data wrows'!D27) -> 9 | F27: 192 | G27: =IF(F27="",_xlfn.XLOOKUP(C27,'Price Averages'!$D$4:$D$103,'Price Averages'!$E$4:$E$103, "FALSE"), F27) -> 192 | H27: 96 | I27: =IF(H27="", _xlfn.XLOOKUP(C27, 'Cost Averages'!$D$4:$D$103,'Cost Averages'!$E$4:$E$103, "FALSE"),H27) -> 96 | J27: =E27*G27 -> 1728 | K27: =E27*I27 -> 864 | L27: =J27-K27 -> 864 | M27: Satisfied | N27: HS-7802 | O27: Healthcare & Safety | P27: 12.801145 | Q27: =CHAR(64+(YEAR(A27)-2014)) -> B | R27: =YEAR(A27) -> 2016 | S27: =IF(Q27=CHAR(64 + (YEAR(A27) - 2014)), 0, 1) -> 0
A28: 42447.175 | B28: 16-2553 | C28: P100 | D28: 5 | E28: =IF(D28="", _xlfn.XLOOKUP(C28,'Median Quantity per product'!$D$4:$D$103,'Median Quantity per product'!$E$4:$E$103, "NA"),'Project Work - Data wrows'!D28) -> 5 | F28: 46 | G28: =IF(F28="",_xlfn.XLOOKUP(C28,'Price Averages'!$D$4:$D$103,'Price Averages'!$E$4:$E$103, "FALSE"), F28) -> 46 | H28: 23 | I28: =IF(H28="", _xlfn.XLOOKUP(C28, 'Cost Averages'!$D$4:$D$103,'Cost Averages'!$E$4:$E$103, "FALSE"),H28) -> 23 | J28: =E28*G28 -> 230 | K28: =E28*I28 -> 115 | L28: =J28-K28 -> 115 | M28: Satisfied | N28: EE-46 | O28: Education | P28: 9.8238489 | Q28: =CHAR(64+(YEAR(A28)-2014)) -> B | R28: =YEAR(A28) -> 2016 | S28: =IF(Q28=CHAR(64 + (YEAR(A28) - 2014)), 0, 1) -> 0
